Workbook

Sheet Pivot table Gender and Category
A4: Sum of Total sales | B4: Gender
A5: Product Category | B5: Female | C5: Male | D5: Grand Total
A6: Beauty | B6: 0.16410088 | C6: 0.150625 | D6: 0.31472588
A7: Clothing | B7: 0.17823465 | C7: 0.16294956 | D7: 0.34118421
A8: Electronics | B8: 0.16827851 | C8: 0.1758114 | D8: 0.34408991
A9: Grand Total | B9: 0.51061404 | C9: 0.48938596 | D9: 1

Sheet Sheet2

Sheet Pivot table Genera and category
A3: Sum of Total sales | B3: Generation
A4: Product Category | B4: Adult | C4: Young Adult | D4: Grand Total
A5: Beauty | B5: 102115 | C5: 41400 | D5: 143515
A6: Clothing | B6: 109430 | C6: 46150 | D6: 155580
A7: Electronics | B7: 121300 | C7: 35605 | D7: 156905
A8: Grand Total | B8: 332845 | C8: 123155 | D8: 456000

Sheet Transactions
A1: Transaction ID | B1: Total Sales | C1: Product category | D1: Concatenate
A2: 10 | B2: =VLOOKUP(A2, retail_sales_dataset!A1:Q1001, COLUMN(O1), FALSE) -> 200 | C2: =VLOOKUP(A2, retail_sales_dataset!A1:Q1001,12, FALSE) -> Clothing | D2: =CONCATENATE(B2,C2) -> 200Clothing
A3: 15 | B3: {=VLOOKUP(A3, retail_sales_dataset!A1:Q1001, COLUMN(retail_sales_dataset!O:O), FALSE)} -> 2000 | C3: =VLOOKUP(A3, retail_sales_dataset!A2:Q1002,12, FALSE) -> Electronics | D3: =CONCATENATE(B3,C3) -> 2000Electronics
A4: 25 | B4: {=VLOOKUP(A4, retail_sales_dataset!A2:Q1002, COLUMN(retail_sales_dataset!O:O), FALSE)} -> 50 | C4: =VLOOKUP(A4, retail_sales_dataset!A3:Q1003,12, FALSE) -> Beauty | D4: =CONCATENATE(B4,C4) -> 50Beauty
A5: 30 | B5: {=VLOOKUP(A5, retail_sales_dataset!A3:Q1003, COLUMN(retail_sales_dataset!O:O), FALSE)} -> 900 | C5: =VLOOKUP(A5, retail_sales_dataset!A4:Q1004,12, FALSE) -> Beauty | D5: =CONCATENATE(B5,C5) -> 900Beauty
A6: 54 | B6: {=VLOOKUP(A6, retail_sales_dataset!A4:Q1004, COLUMN(retail_sales_dataset!O:O), FALSE)} -> 1500 | C6: =VLOOKUP(A6, retail_sales_dataset!A5:Q1005,12, FALSE) -> Electronics | D6: =CONCATENATE(B6,C6) -> 1500Electronics
A7: 55 | B7: {=VLOOKUP(A7, retail_sales_dataset!A5:Q1005, COLUMN(retail_sales_dataset!O:O), FALSE)} -> 120 | C7: =VLOOKUP(A7, retail_sales_dataset!A6:Q1006,12, FALSE) -> Beauty | D7: =CONCATENATE(B7,C7) -> 120Beauty
A8: 67 | B8: {=VLOOKUP(A8, retail_sales_dataset!A6:Q1006, COLUMN(retail_sales_dataset!O:O), FALSE)} -> 1200 | C8: =VLOOKUP(A8, retail_sales_dataset!A7:Q1007,12, FALSE) -> Beauty | D8: =CONCATENATE(B8,C8) -> 1200Beauty
A9: 89 | B9: {=VLOOKUP(A9, retail_sales_dataset!A7:Q1007, COLUMN(retail_sales_dataset!O:O), FALSE)} -> 2000 | C9: =VLOOKUP(A9, retail_sales_dataset!A8:Q1008,12, FALSE) -> Electronics | D9: =CONCATENATE(B9,C9) -> 2000Electronics
A10: 100 | B10: {=VLOOKUP(A10, retail_sales_dataset!A8:Q1008, COLUMN(retail_sales_dataset!O:O), FALSE)} -> 30 | C10: =VLOOKUP(A10, retail_sales_dataset!A9:Q1009,12, FALSE) -> Electronics | D10: =CONCATENATE(B10,C10) -> 30Electronics

Sheet retail_sales_dataset
A1: Transaction ID | B1: Day | C1: Month | D1: Year | E1: Day name | F1: Month name | G1: Date | H1: Customer ID | I1: Gender | J1: Genaration | K1: Age | L1: Product Category | M1: Quantity | N1: Price per Unit | O1: Total sales | P1: Commission 2023 | Q1: Commission 2024
A2: 1 | B2: =DAY(G2) -> 24 | C2: =MONTH(G2) -> 11 | D2: =YEAR(G2) -> 2023 | E2: =TEXT(G2,"DDDD") -> Friday | F2: =TEXT(G2,"MMMM") -> November | G2: 45254 | H2: CUST001 | I2: Male | J2: {=_xlfn.IFS(K2>=50,"Senior",K2>=30,"Adult",K2<30,"Young Adult")} -> Adult | K2: 34 | L2: Beauty | M2: 3 | N2: 50 | O2: =(M2*N2) -> 150 | P2: =O2*$S$3 -> 2.25 | Q2: =O2*$S$4 -> 3 | S2: Rate
A3: 2 | B3: =DAY(G3) -> 27 | C3: =MONTH(G3) -> 2 | D3: =YEAR(G3) -> 2023 | E3: =TEXT(G3,"DDDD") -> Monday | F3: =TEXT(G3,"MMMM") -> February | G3: 44984 | H3: CUST002 | I3: Female | J3: =IF(K3<30, "Young Adult","Adult") -> Young Adult | K3: 26 | L3: Clothing | M3: 2 | N3: 500 | O3: =(M3*N3) -> 1000 | P3: =O3*$S$3 -> 15 | Q3: =O3*$S$4 -> 20 | R3: Commission 2023 | S3: 0.015
A4: 3 | B4: =DAY(G4) -> 13 | C4: =MONTH(G4) -> 1 | D4: =YEAR(G4) -> 2023 | E4: =TEXT(G4,"DDDD") -> Friday | F4: =TEXT(G4,"MMMM") -> January | G4: 44939 | H4: CUST003 | I4: Male | J4: {=_xlfn.IFS(K2>=30,"Senior",K2>=30,"Adult",K2<30,"Young Adult")} -> Senior | K4: 50 | L4: Electronics | M4: 1 | N4: 30 | O4: =(M4*N4) -> 30 | P4: =O4*$S$3 -> 0.45 | Q4: =O4*$S$4 -> 0.6 | R4: Commission 2024 | S4: 0.02
A5: 4 | B5: =DAY(G5) -> 21 | C5: =MONTH(G5) -> 5 | D5: =YEAR(G5) -> 2023 | E5: =TEXT(G5,"DDDD") -> Sunday | F5: =TEXT(G5,"MMMM") -> May | G5: 45067 | H5: CUST004 | I5: Male | J5: =IF(K5<30, "Young Adult","Adult") -> Adult | K5: 37 | L5: Clothing | M5: 1 | N5: 500 | O5: =(M5*N5) -> 500 | P5: =O5*$S$3 -> 7.5 | Q5: =O5*$S$4 -> 10
A6: 5 | B6: =DAY(G6) -> 6 | C6: =MONTH(G6) -> 5 | D6: =YEAR(G6) -> 2023 | E6: =TEXT(G6,"DDDD") -> Saturday | F6: =TEXT(G6,"MMMM") -> May | G6: 45052 | H6: CUST005 | I6: Male | J6: =IF(K6<30, "Young Adult","Adult") -> Adult | K6: 30 | L6: Beauty | M6: 2 | N6: 50 | O6: =(M6*N6) -> 100 | P6: =O6*$S$3 -> 1.5 | Q6: =O6*$S$4 -> 2
A7: 6 | B7: =DAY(G7) -> 25 | C7: =MONTH(G7) -> 4 | D7: =YEAR(G7) -> 2023 | E7: =TEXT(G7,"DDDD") -> Tuesday | F7: =TEXT(G7,"MMMM") -> April | G7: 45041 | H7: CUST006 | I7: Female | J7: =IF(K7<30, "Young Adult","Adult") -> Adult | K7: 45 | L7: Beauty | M7: 1 | N7: 30 | O7: =(M7*N7) -> 30 | P7: =O7*$S$3 -> 0.45 | Q7: =O7*$S$4 -> 0.6
A8: 7 | B8: =DAY(G8) -> 13 | C8: =MONTH(G8) -> 3 | D8: =YEAR(G8) -> 2023 | E8: =TEXT(G8,"DDDD") -> Monday | F8: =TEXT(G8,"MMMM") -> March | G8: 44998 | H8: CUST007 | I8: Male | J8: =IF(K8<30, "Young Adult","Adult") -> Adult | K8: 46 | L8: Clothing | M8: 2 | N8: 25 | O8: =(M8*N8) -> 50 | P8: =O8*$S$3 -> 0.75 | Q8: =O8*$S$4 -> 1
A9: 8 | B9: =DAY(G9) -> 22 | C9: =MONTH(G9) -> 2 | D9: =YEAR(G9) -> 2023 | E9: =TEXT(G9,"DDDD") -> Wednesday | F9: =TEXT(G9,"MMMM") -> February | G9: 44979 | H9: CUST008 | I9: Male | J9: =IF(K9<30, "Young Adult","Adult") -> Adult | K9: 30 | L9: Electronics | M9: 4 | N9: 25 | O9: =(M9*N9) -> 100 | P9: =O9*$S$3 -> 1.5 | Q9: =O9*$S$4 -> 2 | S9: Overrall sales | T9: Quantity
A10: 9 | B10: =DAY(G10) -> 13 | C10: =MONTH(G10) -> 12 | D10: =YEAR(G10) -> 2023 | E10: =TEXT(G10,"DDDD") -> Wednesday | F10: =TEXT(G10,"MMMM") -> December | G10: 45273 | H10: CUST009 | I10: Male | J10: {=_xlfn.IFS(K2>=30,"Senior",K2>=30,"Adult",K2<30,"Young Adult")} -> Senior | K10: 63 | L10: Electronics | M10: 2 | N10: 300 | O10: =(M10*N10) -> 600 | P10: =O10*$S$3 -> 9 | Q10: =O10*$S$4 -> 12 | R10: All products total sales | S10: =SUM(O1:O1001) -> 456000 | T10: Female | U10: Male
A11: 10 | B11: =DAY(G11) -> 7 | C11: =MONTH(G11) -> 10 | D11: =YEAR(G11) -> 2023 | E11: =TEXT(G11,"DDDD") -> Saturday | F11: =TEXT(G11,"MMMM") -> October | G11: 45206 | H11: CUST010 | I11: Female | J11: {=_xlfn.IFS(K2>=30,"Senior",K2>=30,"Adult",K2<30,"Young Adult")} -> Senior | K11: 52 | L11: Clothing | M11: 4 | N11: 50 | O11: =(M11*N11) -> 200 | P11: =O11*$S$3 -> 3 | Q11: =O11*$S$4 -> 4 | R11: Beauty | S11: =SUMIF(L2:L1001,"BEAUTY", O2:O1001) -> 143515 | T11: =SUMIFS(M2:M1001,I2:I1001,"Female",L2:L1001,"Beauty") -> 418 | U11: =SUMIFS(M2:M1001,I2:I1001,"male",L2:L1001,"Beauty") -> 353
A12: 11 | B12: =DAY(G12) -> 14 | C12: =MONTH(G12) -> 2 | D12: =YEAR(G12) -> 2023 | E12: =TEXT(G12,"DDDD") -> Tuesday | F12: =TEXT(G12,"MMMM") -> February | G12: 44971 | H12: CUST011 | I12: Male | J12: =IF(K12<30, "Young Adult","Adult") -> Young Adult | K12: 23 | L12: Clothing | M12: 2 | N12: 50 | O12: =(M12*N12) -> 100 | P12: =O12*$S$3 -> 1.5 | Q12: =O12*$S$4 -> 2 | R12: Clothing | S12: =SUMIF(L3:L1001,"Clothing",O3:O1001) -> 155580 | T12: =SUMIFS(M3:M1001,I3:I1001,"Female",L3:L1001,"Clothing") -> 441 | U12: =SUMIFS(M3:M1001,I3:I1001,"male",L3:L1001,"Clothing") -> 453
A13: 12 | B13: =DAY(G13) -> 30 | C13: =MONTH(G13) -> 10 | D13: =YEAR(G13) -> 2023 | E13: =TEXT(G13,"DDDD") -> Monday | F13: =TEXT(G13,"MMMM") -> October | G13: 45229 | H13: CUST012 | I13: Male | J13: =IF(K13<30, "Young Adult","Adult") -> Adult | K13: 35 | L13: Beauty | M13: 3 | N13: 25 | O13: =(M13*N13) -> 75 | P13: =O13*$S$3 -> 1.125 | Q13: =O13*$S$4 -> 1.5 | R13: Electronics | S13: =SUMIF(L4:L1001,"Electronics",O4:O1001) -> 156905 | T13: =SUMIFS(M2:M1001,I2:I1001,"Female",L2:L1001,"Electronics") -> 439 | U13: =SUMIFS(M2:M1001,I2:I1001,"male",L2:L1001,"Electronics") -> 410
A14: 13 | B14: =DAY(G14) -> 5 | C14: =MONTH(G14) -> 8 | D14: =YEAR(G14) -> 2023 | E14: =TEXT(G14,"DDDD") -> Saturday | F14: =TEXT(G14,"MMMM") -> August | G14: 45143 | H14: CUST013 | I14: Male | J14: =IF(K14<30, "Young Adult","Adult") -> Young Adult | K14: 22 | L14: Electronics | M14: 3 | N14: 500 | O14: =(M14*N14) -> 1500 | P14: =O14*$S$3 -> 22.5 | Q14: =O14*$S$4 -> 30
A15: 14 | B15: =DAY(G15) -> 17 | C15: =MONTH(G15) -> 1 | D15: =YEAR(G15) -> 2023 | E15: =TEXT(G15,"DDDD") -> Tuesday | F15: =TEXT(G15,"MMMM") -> January | G15: 44943 | H15: CUST014 | I15: Male | J15: {=_xlfn.IFS(K2>=30,"Senior",K2>=30,"Adult",K2<30,"Young Adult")} -> Senior | K15: 64 | L15: Clothing | M15: 4 | N15: 30 | O15: =(M15*N15) -> 120 | P15: =O15*$S$3 -> 1.8 | Q15: =O15*$S$4 -> 2.4
A16: 15 | B16: =DAY(G16) -> 16 | C16: =MONTH(G16) -> 1 | D16: =YEAR(G16) -> 2023 | E16: =TEXT(G16,"DDDD") -> Monday | F16: =TEXT(G16,"MMMM") -> January | G16: 44942 | H16: CUST015 | I16: Female | J16: =IF(K16<30, "Young Adult","Adult") -> Adult | K16: 42 | L16: Electronics | M16: 4 | N16: 500 | O16: =(M16*N16) -> 2000 | P16: =O16*$S$3 -> 30 | Q16: =O16*$S$4 -> 40
A17: 16 | B17: =DAY(G17) -> 17 | C17: =MONTH(G17) -> 2 | D17: =YEAR(G17) -> 2023 | E17: =TEXT(G17,"DDDD") -> Friday | F17: =TEXT(G17,"MMMM") -> February | G17: 44974 | H17: CUST016 | I17: Male | J17: =IF(K17<30, "Young Adult","Adult") -> Young Adult | K17: 19 | L17: Clothing | M17: 3 | N17: 500 | O17: =(M17*N17) -> 1500 | P17: =O17*$S$3 -> 22.5 | Q17: =O17*$S$4 -> 30
A18: 17 | B18: =DAY(G18) -> 22 | C18: =MONTH(G18) -> 4 | D18: =YEAR(G18) -> 2023 | E18: =TEXT(G18,"DDDD") -> Saturday | F18: =TEXT(G18,"MMMM") -> April | G18: 45038 | H18: CUST017 | I18: Female | J18: =IF(K18<30, "Young Adult","Adult") -> Young Adult | K18: 27 | L18: Clothing | M18: 4 | N18: 25 | O18: =(M18*N18) -> 100 | P18: =O18*$S$3 -> 1.5 | Q18: =O18*$S$4 -> 2
A19: 18 | B19: =DAY(G19) -> 30 | C19: =MONTH(G19) -> 4 | D19: =YEAR(G19) -> 2023 | E19: =TEXT(G19,"DDDD") -> Sunday | F19: =TEXT(G19,"MMMM") -> April | G19: 45046 | H19: CUST018 | I19: Female | J19: =IF(K19<30, "Young Adult","Adult") -> Adult | K19: 47 | L19: Electronics | M19: 2 | N19: 25 | O19: =(M19*N19) -> 50 | P19: =O19*$S$3 -> 0.75 | Q19: =O19*$S$4 -> 1
A20: 19 | B20: =DAY(G20) -> 16 | C20: =MONTH(G20) -> 9 | D20: =YEAR(G20) -> 2023 | E20: =TEXT(G20,"DDDD") -> Saturday | F20: =TEXT(G20,"MMMM") -> September | G20: 45185 | H20: CUST019 | I20: Female | J20: {=_xlfn.IFS(K2>=30,"Senior",K2>=30,"Adult",K2<30,"Young Adult")} -> Senior | K20: 62 | L20: Clothing | M20: 2 | N20: 25 | O20: =(M20*N20) -> 50 | P20: =O20*$S$3 -> 0.75 | Q20: =O20*$S$4 -> 1
A21: 20 | B21: =DAY(G21) -> 5 | C21: =MONTH(G21) -> 11 | D21: =YEAR(G21) -> 2023 | E21: =TEXT(G21,"DDDD") -> Sunday | F21: =TEXT(G21,"MMMM") -> November | G21: 45235 | H21: CUST020 | I21: Male | J21: =IF(K21<30, "Young Adult","Adult") -> Young Adult | K21: 22 | L21: Clothing | M21: 3 | N21: 300 | O21: =(M21*N21) -> 900 | P21: =O21*$S$3 -> 13.5 | Q21: =O21*$S$4 -> 18
A22: 21 | B22: =DAY(G22) -> 14 | C22: =MONTH(G22) -> 1 | D22: =YEAR(G22) -> 2023 | E22: =TEXT(G22,"DDDD") -> Saturday | F22: =TEXT(G22,"MMMM") -> January | G22: 44940 | H22: CUST021 | I22: Female | J22: {=_xlfn.IFS(K2>=30,"Senior",K2>=30,"Adult",K2<30,"Young Adult")} -> Senior | K22: 50 | L22: Beauty | M22: 1 | N22: 500 | O22: =(M22*N22) -> 500 | P22: =O22*$S$3 -> 7.5 | Q22: =O22*$S$4 -> 10
A23: 22 | B23: =DAY(G23) -> 15 | C23: =MONTH(G23) -> 10 | D23: =YEAR(G23) -> 2023 | E23: =TEXT(G23,"DDDD") -> Sunday | F23: =TEXT(G23,"MMMM") -> October | G23: 45214 | H23: CUST022 | I23: Male | J23: =IF(K23<30, "Young Adult","Adult") -> Young Adult | K23: 18 | L23: Clothing | M23: 2 | N23: 50 | O23: =(M23*N23) -> 100 | P23: =O23*$S$3 -> 1.5 | Q23: =O23*$S$4 -> 2
A24: 23 | B24: =DAY(G24) -> 12 | C24: =MONTH(G24) -> 4 | D24: =YEAR(G24) -> 2023 | E24: =TEXT(G24,"DDDD") -> Wednesday | F24: =TEXT(G24,"MMMM") -> April | G24: 45028 | H24: CUST023 | I24: Female | J24: =IF(K24<30, "Young Adult","Adult") -> Adult | K24: 35 | L24: Clothing | M24: 4 | N24: 30 | O24: =(M24*N24) -> 120 | P24: =O24*$S$3 -> 1.8 | Q24: =O24*$S$4 -> 2.4
A25: 24 | B25: =DAY(G25) -> 29 | C25: =MONTH(G25) -> 11 | D25: =YEAR(G25) -> 2023 | E25: =TEXT(G25,"DDDD") -> Wednesday | F25: =TEXT(G25,"MMMM") -> November | G25: 45259 | H25: CUST024 | I25: Female | J25: =IF(K25<30, "Young Adult","Adult") -> Adult | K25: 49 | L25: Clothing | M25: 1 | N25: 300 | O25: =(M25*N25) -> 300 | P25: =O25*$S$3 -> 4.5 | Q25: =O25*$S$4 -> 6
A26: 25 | B26: =DAY(G26) -> 26 | C26: =MONTH(G26) -> 12 | D26: =YEAR(G26) -> 2023 | E26: =TEXT(G26,"DDDD") -> Tuesday | F26: =TEXT(G26,"MMMM") -> December | G26: 45286 | H26: CUST025 | I26: Female | J26: {=_xlfn.IFS(K2>=30,"Senior",K2>=30,"Adult",K2<30,"Young Adult")} -> Senior | K26: 64 | L26: Beauty | M26: 1 | N26: 50 | O26: =(M26*N26) -> 50 | P26: =O26*$S$3 -> 0.75 | Q26: =O26*$S$4 -> 1
A27: 26 | B27: =DAY(G27) -> 7 | C27: =MONTH(G27) -> 10 | D27: =YEAR(G27) -> 2023 | E27: =TEXT(G27,"DDDD") -> Saturday | F27: =TEXT(G27,"MMMM") -> October | G27: 45206 | H27: CUST026 | I27: Female | J27: =IF(K27<30, "Young Adult","Adult") -> Young Adult | K27: 28 | L27: Electronics | M27: 2 | N27: 500 | O27: =(M27*N27) -> 1000 | P27: =O27*$S$3 -> 15 | Q27: =O27*$S$4 -> 20
A28: 27 | B28: =DAY(G28) -> 3 | C28: =MONTH(G28) -> 8 | D28: =YEAR(G28) -> 2023 | E28: =TEXT(G28,"DDDD") -> Thursday | F28: =TEXT(G28,"MMMM") -> August | G28: 45141 | H28: CUST027 | I28: Female | J28: =IF(K28<30, "Young Adult","Adult") -> Adult | K28: 38 | L28: Beauty | M28: 2 | N28: 25 | O28: =(M28*N28) -> 50 | P28: =O28*$S$3 -> 0.75 | Q28: =O28*$S$4 -> 1
A29: 28 | B29: =DAY(G29) -> 23 | C29: =MONTH(G29) -> 4 | D29: =YEAR(G29) -> 2023 | E29: =TEXT(G29,"DDDD") -> Sunday | F29: =TEXT(G29,"MMMM") -> April | G29: 45039 | H29: CUST028 | I29: Female | J29: =IF(K29<30, "Young Adult","Adult") -> Adult | K29: 43 | L29: Beauty | M29: 1 | N29: 500 | O29: =(M29*N29) -> 500 | P29: =O29*$S$3 -> 7.5 | Q29: =O29*$S$4 -> 10
A30: 29 | B30: =DAY(G30) -> 18 | C30: =MONTH(G30) -> 8 | D30: =YEAR(G30) -> 2023 | E30: =TEXT(G30,"DDDD") -> Friday | F30: =TEXT(G30,"MMMM") -> August | G30: 45156 | H30: CUST029 | I30: Female | J30: =IF(K30<30, "Young Adult","Adult") -> Adult | K30: 42 | L30: Electronics | M30: 1 | N30: 30 | O30: =(M30*N30) -> 30 | P30: =O30*$S$3 -> 0.45 | Q30: =O30*$S$4 -> 0.6
A31: 30 | B31: =DAY(G31) -> 29 | C31: =MONTH(G31) -> 10 | D31: =YEAR(G31) -> 2023 | E31: =TEXT(G31,"DDDD") -> Sunday | F31: =TEXT(G31,"MMMM") -> October | G31: 45228 | H31: CUST030 | I31: Female | J31: =IF(K31<30, "Young Adult","Adult") -> Adult | K31: 39 | L31: Beauty | M31: 3 | N31: 300 | O31: =(M31*N31) -> 900 | P31: =O31*$S$3 -> 13.5 | Q31: =O31*$S$4 -> 18
A32: 31 | B32: =DAY(G32) -> 23 | C32: =MONTH(G32) -> 5 | D32: =YEAR(G32) -> 2023 | E32: =TEXT(G32,"DDDD") -> Tuesday | F32: =TEXT(G32,"MMMM") -> May | G32: 45069 | H32: CUST031 | I32: Male | J32: =IF(K32<30, "Young Adult","Adult") -> Adult | K32: 44 | L32: Electronics | M32: 4 | N32: 300 | O32: =(M32*N32) -> 1200 | P32: =O32*$S$3 -> 18 | Q32: =O32*$S$4 -> 24
A33: 32 | B33: =DAY(G33) -> 4 | C33: =MONTH(G33) -> 1 | D33: =YEAR(G33) -> 2023 | E33: =TEXT(G33,"DDDD") -> Wednesday | F33: =TEXT(G33,"MMMM") -> January | G33: 44930 | H33: CUST032 | I33: Male | J33: =IF(K33<30, "Young Adult","Adult") -> Adult | K33: 30 | L33: Beauty | M33: 3 | N33: 30 | O33: =(M33*N33) -> 90 | P33: =O33*$S$3 -> 1.35 | Q33: =O33*$S$4 -> 1.8
A34: 33 | B34: =DAY(G34) -> 23 | C34: =MONTH(G34) -> 3 | D34: =YEAR(G34) -> 2023 | E34: =TEXT(G34,"DDDD") -> Thursday | F34: =TEXT(G34,"MMMM") -> March | G34: 45008 | H34: CUST033 | I34: Female | J34: {=_xlfn.IFS(K2>=30,"Senior",K2>=30,"Adult",K2<30,"Young Adult")} -> Senior | K34: 50 | L34: Electronics | M34: 2 | N34: 50 | O34: =(M34*N34) -> 100 | P34: =O34*$S$3 -> 1.5 | Q34: =O34*$S$4 -> 2
A35: 34 | B35: =DAY(G35) -> 24 | C35: =MONTH(G35) -> 12 | D35: =YEAR(G35) -> 2023 | E35: =TEXT(G35,"DDDD") -> Sunday | F35: =TEXT(G35,"MMMM") -> December | G35: 45284 | H35: CUST034 | I35: Female | J35: {=_xlfn.IFS(K2>=30,"Senior",K2>=30,"Adult",K2<30,"Young Adult")} -> Senior | K35: 51 | L35: Clothing | M35: 3 | N35: 50 | O35: =(M35*N35) -> 150 | P35: =O35*$S$3 -> 2.25 | Q35: =O35*$S$4 -> 3
A36: 35 | B36: =DAY(G36) -> 5 | C36: =MONTH(G36) -> 8 | D36: =YEAR(G36) -> 2023 | E36: =TEXT(G36,"DDDD") -> Saturday | F36: =TEXT(G36,"MMMM") -> August | G36: 45143 | H36: CUST035 | I36: Female | J36: {=_xlfn.IFS(K2>=30,"Senior",K2>=30,"Adult",K2<30,"Young Adult")} -> Senior | K36: 58 | L36: Beauty | M36: 3 | N36: 300 | O36: =(M36*N36) -> 900 | P36: =O36*$S$3 -> 13.5 | Q36: =O36*$S$4 -> 18
A37: 36 | B37: =DAY(G37) -> 24 | C37: =MONTH(G37) -> 6 | D37: =YEAR(G37) -> 2023 | E37: =TEXT(G37,"DDDD") -> Saturday | F37: =TEXT(G37,"MMMM") -> June | G37: 45101 | H37: CUST036 | I37: Male | J37: {=_xlfn.IFS(K2>=30,"Senior",K2>=30,"Adult",K2<30,"Young Adult")} -> Senior | K37: 52 | L37: Beauty | M37: 3 | N37: 300 | O37: =(M37*N37) -> 900 | P37: =O37*$S$3 -> 13.5 | Q37: =O37*$S$4 -> 18
A38: 37 | B38: =DAY(G38) -> 23 | C38: =MONTH(G38) -> 5 | D38: =YEAR(G38) -> 2023 | E38: =TEXT(G38,"DDDD") -> Tuesday | F38: =TEXT(G38,"MMMM") -> May | G38: 45069 | H38: CUST037 | I38: Female | J38: =IF(K38<30, "Young Adult","Adult") -> Young Adult | K38: 18 | L38: Beauty | M38: 3 | N38: 25 | O38: =(M38*N38) -> 75 | P38: =O38*$S$3 -> 1.125 | Q38: =O38*$S$4 -> 1.5
A39: 38 | B39: =DAY(G39) -> 21 | C39: =MONTH(G39) -> 3 | D39: =YEAR(G39) -> 2023 | E39: =TEXT(G39,"DDDD") -> Tuesday | F39: =TEXT(G39,"MMMM") -> March | G39: 45006 | H39: CUST038 | I39: Male | J39: =IF(K39<30, "Young Adult","Adult") -> Adult | K39: 38 | L39: Beauty | M39: 4 | N39: 50 | O39: =(M39*N39) -> 200 | P39: =O39*$S$3 -> 3 | Q39: =O39*$S$4 -> 4
A40: 39 | B40: =DAY(G40) -> 21 | C40: =MONTH(G40) -> 4 | D40: =YEAR(G40) -> 2023 | E40: =TEXT(G40,"DDDD") -> Friday | F40: =TEXT(G40,"MMMM") -> April | G40: 45037 | H40: CUST039 | I40: Male | J40: =IF(K40<30, "Young Adult","Adult") -> Young Adult | K40: 23 | L40: Clothing | M40: 4 | N40: 30 | O40: =(M40*N40) -> 120 | P40: =O40*$S$3 -> 1.8 | Q40: =O40*$S$4 -> 2.4
...
